Workbook

Sheet WBS
A2: 줍 프로젝트 WBS
A3: 계획 시작 | B3: 46294 | D3: MVP 완료 목표 | E3: 46332
A4: 진행 중 | B4: =COUNTIF(J9:J45,"진행중")+COUNTIF('그래프DB 일정'!J9:J16,"진행중") | D4: 완료 | E4: =COUNTIF(J9:J45,"완료")+COUNTIF('그래프DB 일정'!J9:J16,"완료")
A5: 전체 진행률 | B5: =AVERAGE(K9:K45,'그래프DB 일정'!K9:K16) | D5: 계획 항목 | E5: =COUNTA(A9:A45)+COUNTA('그래프DB 일정'!A9:A16)
A6: 핵심 흐름: 메인→로그인→첫 로그인 사용자만 튜토리얼 1회→관심종목→관계 그래프→노드 상세→메인. 재방문은 메인으로 직행. 뉴스 자동 수집·영향 분석 포함.
A8: WBS | B8: 구분 | C8: 단계 | D8: 작업 | E8: 완료 기준 | F8: 담당 역할 | G8: 시작일 | H8: 종료일 | I8: 참조·의존 | J8: 상태 | K8: 진행률 | L8: 위험·비고 | M8: 46293 | N8: 46301 | O8: 46307 | P8: 46314 | Q8: 46321 | R8: 46328
A9: 1.1 | B9: 작업 | C9: 범위 확정 | D9: MVP 기능·제약 확정 | E9: 로그인·최초 1회 튜토리얼·관심종목 그래프/노드 상세·mock 계좌·뉴스 자동 수집/분석 범위 확정 | F9: B1 | G9: 46294 | H9: 46297 | J9: 예정 | K9: 0 | L9: 계좌 기능은 가상계좌 mock 데이터로 한정 | M9: =IF(AND($G9<=N$8-1,$H9>=M$8),"X","") | N9: =IF(AND($G9<=O$8-1,$H9>=N$8),"X","") | O9: =IF(AND($G9<=P$8-1,$H9>=O$8),"X","") | P9: =IF(AND($G9<=Q$8-1,$H9>=P$8),"X","") | Q9: =IF(AND($G9<=R$8-1,$H9>=Q$8),"X","") | R9: =IF(AND($G9<=R$8+4,$H9>=R$8),"X","")
A10: 1.2 | B10: 작업 | C10: 범위 확정 | D10: 최초·재방문 사용자 흐름 확정 | E10: 메인→로그인→첫 사용자 튜토리얼, 재방문 메인 직행, 오류 분기 확정 | F10: B5 | G10: 46294 | H10: 46296 | J10: 예정 | K10: 0 | L10: 로그인 전 메인과 로그인 후 개인화 메인의 상태 구분 | M10: =IF(AND($G10<=N$8-1,$H10>=M$8),"X","") | N10: =IF(AND($G10<=O$8-1,$H10>=N$8),"X","") | O10: =IF(AND($G10<=P$8-1,$H10>=O$8),"X","") | P10: =IF(AND($G10<=Q$8-1,$H10>=P$8),"X","") | Q10: =IF(AND($G10<=R$8-1,$H10>=Q$8),"X","") | R10: =IF(AND($G10<=R$8+4,$H10>=R$8),"X","")
A11: 1.3 | B11: 작업 | C11: 범위 확정 | D11: 화면·API 계약 초안 | E11: 로그인 후 튜토리얼 분기·관심종목·그래프·노드 상세 API 계약 | F11: B4 | G11: 46295 | H11: 46297 | I11: 1.2 | J11: 예정 | K11: 0 | L11: B4가 화면별 API 계약 초안, B1·F1 검토 | M11: =IF(AND($G11<=N$8-1,$H11>=M$8),"X","") | N11: =IF(AND($G11<=O$8-1,$H11>=N$8),"X","") | O11: =IF(AND($G11<=P$8-1,$H11>=O$8),"X","") | P11: =IF(AND($G11<=Q$8-1,$H11>=P$8),"X","") | Q11: =IF(AND($G11<=R$8-1,$H11>=Q$8),"X","") | R11: =IF(AND($G11<=R$8+4,$H11>=R$8),"X","")
A12: 1.4 | B12: 작업 | C12: 범위 확정 | D12: 가상계좌 mock 범위 확정 | E12: 가상계좌 잔고·보유종목·거래내역 mock 필드와 샘플 데이터 확정 | F12: B3 | G12: 46295 | H12: 46297 | J12: 예정 | K12: 0 | L12: B3가 mock 데이터 설계, B4 계좌 API에 인계 | M12: =IF(AND($G12<=N$8-1,$H12>=M$8),"X","") | N12: =IF(AND($G12<=O$8-1,$H12>=N$8),"X","") | O12: =IF(AND($G12<=P$8-1,$H12>=O$8),"X","") | P12: =IF(AND($G12<=Q$8-1,$H12>=P$8),"X","") | Q12: =IF(AND($G12<=R$8-1,$H12>=Q$8),"X","") | R12: =IF(AND($G12<=R$8+4,$H12>=R$8),"X","")
A13: M1 | B13: 마일스톤 | C13: 범위 확정 | D13: MVP 범위 승인 | E13: mock 데이터 범위 포함 개발 범위·완료 기준 합의 | F13: 전체 | G13: 46297 | H13: 46297 | I13: 1.1, 1.3, 1.4 | J13: 예정 | K13: 0 | M13: =IF(AND($G13<=N$8-1,$H13>=M$8),"X","") | N13: =IF(AND($G13<=O$8-1,$H13>=N$8),"X","") | O13: =IF(AND($G13<=P$8-1,$H13>=O$8),"X","") | P13: =IF(AND($G13<=Q$8-1,$H13>=P$8),"X","") | Q13: =IF(AND($G13<=R$8-1,$H13>=Q$8),"X","") | R13: =IF(AND($G13<=R$8+4,$H13>=R$8),"X","")
A14: 2.1 | B14: 작업 | C14: 화면 설계 | D14: 정보 구조·흐름 와이어프레임 | E14: 로그인 전 메인·첫 방문 튜토리얼·노드 상세·개인화 메인 화면 구조 | F14: B5 | G14: 46295 | H14: 46302 | I14: 1.2 | J14: 예정 | K14: 0 | L14: B5가 와이어프레임 작성, F1 검토 | M14: =IF(AND($G14<=N$8-1,$H14>=M$8),"X","") | N14: =IF(AND($G14<=O$8-1,$H14>=N$8),"X","") | O14: =IF(AND($G14<=P$8-1,$H14>=O$8),"X","") | P14: =IF(AND($G14<=Q$8-1,$H14>=P$8),"X","") | Q14: =IF(AND($G14<=R$8-1,$H14>=Q$8),"X","") | R14: =IF(AND($G14<=R$8+4,$H14>=R$8),"X","")
A15: 2.2 | B15: 작업 | C15: 화면 설계 | D15: UI 규칙·컴포넌트 정의 | E15: 색·글자·버튼·입력·알림·상태별 규칙 | F15: F1 | G15: 46301 | H15: 46303 | I15: 2.1 | J15: 예정 | K15: 0 | L15: F1이 재사용 UI 규칙 작성, B5 리뷰 | M15: =IF(AND($G15<=N$8-1,$H15>=M$8),"X","") | N15: =IF(AND($G15<=O$8-1,$H15>=N$8),"X","") | O15: =IF(AND($G15<=P$8-1,$H15>=O$8),"X","") | P15: =IF(AND($G15<=Q$8-1,$H15>=P$8),"X","") | Q15: =IF(AND($G15<=R$8-1,$H15>=Q$8),"X","") | R15: =IF(AND($G15<=R$8+4,$H15>=R$8),"X","")
A16: 2.3 | B16: 작업 | C16: 화면 설계 | D16: 로그인·가입·비회원 화면 디자인 | E16: 정상·오류·제한 안내 시안 | F16: F1 | G16: 46301 | H16: 46307 | I16: 2.1 | J16: 예정 | K16: 0 | L16: F1 주도, B1 인증 상태 검토 | M16: =IF(AND($G16<=N$8-1,$H16>=M$8),"X","") | N16: =IF(AND($G16<=O$8-1,$H16>=N$8),"X","") | O16: =IF(AND($G16<=P$8-1,$H16>=O$8),"X","") | P16: =IF(AND($G16<=Q$8-1,$H16>=P$8),"X","") | Q16: =IF(AND($G16<=R$8-1,$H16>=Q$8),"X","") | R16: =IF(AND($G16<=R$8+4,$H16>=R$8),"X","")
A17: 2.4 | B17: 작업 | C17: 화면 설계 | D17: 튜토리얼·노드 상세 화면 설계 | E17: 관심종목 선택→그래프 표시→노드 클릭→상세 확인→메인 이동 시안 | F17: B3 | G17: 46302 | H17: 46308 | I17: 2.1, 2.2 | J17: 예정 | K17: 0 | L17: 관심종목 선택부터 노드 상세까지 실제 기능을 체험하는 순서 | M17: =IF(AND($G17<=N$8-1,$H17>=M$8),"X","") | N17: =IF(AND($G17<=O$8-1,$H17>=N$8),"X","") | O17: =IF(AND($G17<=P$8-1,$H17>=O$8),"X","") | P17: =IF(AND($G17<=Q$8-1,$H17>=P$8),"X","") | Q17: =IF(AND($G17<=R$8-1,$H17>=Q$8),"X","") | R17: =IF(AND($G17<=R$8+4,$H17>=R$8),"X","")
A18: 2.5 | B18: 작업 | C18: 화면 설계 | D18: 개인화 메인·반응형 설계 | E18: 관심종목 연결 그래프·내 종목 관련 노드/뉴스·모바일 시안 | F18: B2 | G18: 46303 | H18: 46308 | I18: 2.1, 2.2 | J18: 예정 | K18: 0 | L18: B2가 그래프·메인 데이터 표시 설계, B5 화면 구현에 인계 | M18: =IF(AND($G18<=N$8-1,$H18>=M$8),"X","") | N18: =IF(AND($G18<=O$8-1,$H18>=N$8),"X","") | O18: =IF(AND($G18<=P$8-1,$H18>=O$8),"X","") | P18: =IF(AND($G18<=Q$8-1,$H18>=P$8),"X","") | Q18: =IF(AND($G18<=R$8-1,$H18>=Q$8),"X","") | R18: =IF(AND($G18<=R$8+4,$H18>=R$8),"X","")
A19: M2 | B19: 마일스톤 | C19: 화면 설계 | D19: 핵심 화면 승인 | E19: 화면·상태·인터랙션 개발 인계 | F19: 전체 | G19: 46308 | H19: 46308 | I19: 2.3, 2.4, 2.5 | J19: 예정 | K19: 0 | L19: F1·B2·B3·B5 화면 합동 검토 | M19: =IF(AND($G19<=N$8-1,$H19>=M$8),"X","") | N19: =IF(AND($G19<=O$8-1,$H19>=N$8),"X","") | O19: =IF(AND($G19<=P$8-1,$H19>=O$8),"X","") | P19: =IF(AND($G19<=Q$8-1,$H19>=P$8),"X","") | Q19: =IF(AND($G19<=R$8-1,$H19>=Q$8),"X","") | R19: =IF(AND($G19<=R$8+4,$H19>=R$8),"X","")
A20: 3.1 | B20: 작업 | C20: 개발 기반 | D20: 프로젝트·배포 환경 준비 | E20: 저장소·개발/스테이징 환경·빌드 실행 | F20: A1 | G20: 46296 | H20: 46302 | J20: 예정 | K20: 0 | L20: A1 주도, B1 개발환경 연결 지원 | M20: =IF(AND($G20<=N$8-1,$H20>=M$8),"X","") | N20: =IF(AND($G20<=O$8-1,$H20>=N$8),"X","") | O20: =IF(AND($G20<=P$8-1,$H20>=O$8),"X","") | P20: =IF(AND($G20<=Q$8-1,$H20>=P$8),"X","") | Q20: =IF(AND($G20<=R$8-1,$H20>=Q$8),"X","") | R20: =IF(AND($G20<=R$8+4,$H20>=R$8),"X","")
A21: 3.2 | B21: 작업 | C21: 개발 기반 | D21: 회원·설정 데이터 구조 | E21: 계정·관심종목·최초 튜토리얼 완료 여부와 완료 시각 저장 구조 | F21: B1 | G21: 46301 | H21: 46303 | I21: 1.3 | J21: 예정 | K21: 0 | M21: =IF(AND($G21<=N$8-1,$H21>=M$8),"X","") | N21: =IF(AND($G21<=O$8-1,$H21>=N$8),"X","") | O21: =IF(AND($G21<=P$8-1,$H21>=O$8),"X","") | P21: =IF(AND($G21<=Q$8-1,$H21>=P$8),"X","") | Q21: =IF(AND($G21<=R$8-1,$H21>=Q$8),"X","") | R21: =IF(AND($G21<=R$8+4,$H21>=R$8),"X","")
A22: 3.3 | B22: 작업 | C22: 개발 기반 | D22: 가상계좌·질문 예시 데이터 준비 | E22: 가상계좌·AI 질문 예시 답변 데이터 준비. 뉴스는 자동 수집·분석 일정에서 별도 구축 | F22: A1 | G22: 46302 | H22: 46308 | I22: 1.3 | J22: 예정 | K22: 0 | L22: AI 질문은 예시 답변. 뉴스 영향 분석은 N6~N7에서 실제 자동 처리 | M22: =IF(AND($G22<=N$8-1,$H22>=M$8),"X","") | N22: =IF(AND($G22<=O$8-1,$H22>=N$8),"X","") | O22: =IF(AND($G22<=P$8-1,$H22>=O$8),"X","") | P22: =IF(AND($G22<=Q$8-1,$H22>=P$8),"X","") | Q22: =IF(AND($G22<=R$8-1,$H22>=Q$8),"X","") | R22: =IF(AND($G22<=R$8+4,$H22>=R$8),"X","")
A23: 4.1 | B23: 작업 | C23: 백엔드 | D23: 회원가입·로그인 API | E23: 가입 검증·아이디 중복·인증 실패 처리 | F23: B1 | G23: 46303 | H23: 46311 | I23: 3.1, 3.2 | J23: 예정 | K23: 0 | M23: =IF(AND($G23<=N$8-1,$H23>=M$8),"X","") | N23: =IF(AND($G23<=O$8-1,$H23>=N$8),"X","") | O23: =IF(AND($G23<=P$8-1,$H23>=O$8),"X","") | P23: =IF(AND($G23<=Q$8-1,$H23>=P$8),"X","") | Q23: =IF(AND($G23<=R$8-1,$H23>=Q$8),"X","") | R23: =IF(AND($G23<=R$8+4,$H23>=R$8),"X","")
A24: 4.2 | B24: 작업 | C24: 백엔드 | D24: 세션·비회원 권한 | E24: 비회원 제한 기능과 안내 조건 구현 | F24: B1 | G24: 46308 | H24: 46315 | I24: 4.1 | J24: 예정 | K24: 0 | M24: =IF(AND($G24<=N$8-1,$H24>=M$8),"X","") | N24: =IF(AND($G24<=O$8-1,$H24>=N$8),"X","") | O24: =IF(AND($G24<=P$8-1,$H24>=O$8),"X","") | P24: =IF(AND($G24<=Q$8-1,$H24>=P$8),"X","") | Q24: =IF(AND($G24<=R$8-1,$H24>=Q$8),"X","") | R24: =IF(AND($G24<=R$8+4,$H24>=R$8),"X","")
A25: 4.3 | B25: 작업 | C25: 백엔드 | D25: 가상계좌 데이터 제공 API | E25: mock 보유종목 목록·계좌 상태 응답 | F25: B4 | G25: 46314 | H25: 46318 | I25: G8, 3.3 | J25: 예정 | K25: 0 | L25: G8 인계 이후 B4가 가상계좌 mock API 구현 | M25: =IF(AND($G25<=N$8-1,$H25>=M$8),"X","") | N25: =IF(AND($G25<=O$8-1,$H25>=N$8),"X","") | O25: =IF(AND($G25<=P$8-1,$H25>=O$8),"X","") | P25: =IF(AND($G25<=Q$8-1,$H25>=P$8),"X","") | Q25: =IF(AND($G25<=R$8-1,$H25>=Q$8),"X","") | R25: =IF(AND($G25<=R$8+4,$H25>=R$8),"X","")
A26: 4.4 | B26: 작업 | C26: 백엔드 | D26: 관심종목 검색·저장 API | E26: 튜토리얼에서 관심종목 1개 이상 선택·회원별 저장·재조회 | F26: B4 | G26: 46309 | H26: 46318 | I26: 3.2, 3.3 | J26: 예정 | K26: 0 | L26: B4 주도, B1이 사용자별 저장 규칙 검토 | M26: =IF(AND($G26<=N$8-1,$H26>=M$8),"X","") | N26: =IF(AND($G26<=O$8-1,$H26>=N$8),"X","") | O26: =IF(AND($G26<=P$8-1,$H26>=O$8),"X","") | P26: =IF(AND($G26<=Q$8-1,$H26>=P$8),"X","") | Q26: =IF(AND($G26<=R$8-1,$H26>=Q$8),"X","") | R26: =IF(AND($G26<=R$8+4,$H26>=R$8),"X","")
A27: 4.5 | B27: 작업 | C27: 백엔드 | D27: 최초 튜토리얼 분기·완료 API | E27: 로그인 후 완료 상태 조회, 처음이면 튜토리얼, 완료 후 재방문은 메인으로 이동 | F27: B1 | G27: 46316 | H27: 46322 | I27: 4.1, 3.2 | J27: 예정 | K27: 0 | L27: 그래프 노드 상세 확인 후 완료 처리. 재방문 시 자동 재실행 없음 | M27: =IF(AND($G27<=N$8-1,$H27>=M$8),"X","") | N27: =IF(AND($G27<=O$8-1,$H27>=N$8),"X","") | O27: =IF(AND($G27<=P$8-1,$H27>=O$8),"X","") | P27: =IF(AND($G27<=Q$8-1,$H27>=P$8),"X","") | Q27: =IF(AND($G27<=R$8-1,$H27>=Q$8),"X","") | R27: =IF(AND($G27<=R$8+4,$H27>=R$8),"X","")
A28: 5.1 | B28: 작업 | C28: 프론트엔드 | D28: 프론트 환경 적응·공통 UI | E28: 개발환경 실행·버튼/폼/알림 컴포넌트·페어 리뷰 | F28: F1 | G28: 46301 | H28: 46310 | I28: 2.1 초안, 3.1 | J28: 예정 | K28: 0 | L28: F1 공통 UI 구현, B5 코드 리뷰 | M28: =IF(AND($G28<=N$8-1,$H28>=M$8),"X","") | N28: =IF(AND($G28<=O$8-1,$H28>=N$8),"X","") | O28: =IF(AND($G28<=P$8-1,$H28>=O$8),"X","") | P28: =IF(AND($G28<=Q$8-1,$H28>=P$8),"X","") | Q28: =IF(AND($G28<=R$8-1,$H28>=Q$8),"X","") | R28: =IF(AND($G28<=R$8+4,$H28>=R$8),"X","")
A29: 5.2 | B29: 작업 | C29: 프론트엔드 | D29: 로그인·가입·비회원 화면 | E29: 입력 검증·실패 문구·기능 제한 안내 | F29: F1 | G29: 46309 | H29: 46317 | I29: 5.1, 2.3 | J29: 예정 | K29: 0 | L29: F1 인증 화면, B1 API 연동 지원 | M29: =IF(AND($G29<=N$8-1,$H29>=M$8),"X","") | N29: =IF(AND($G29<=O$8-1,$H29>=N$8),"X","") | O29: =IF(AND($G29<=P$8-1,$H29>=O$8),"X","") | P29: =IF(AND($G29<=Q$8-1,$H29>=P$8),"X","") | Q29: =IF(AND($G29<=R$8-1,$H29>=Q$8),"X","") | R29: =IF(AND($G29<=R$8+4,$H29>=R$8),"X","")
A30: 5.3 | B30: 작업 | C30: 프론트엔드 | D30: 튜토리얼 관심종목 선택 화면 | E30: 관심종목 검색·선택, 0개이면 다음 진행 차단 | F30: F1 | G30: 46315 | H30: 46322 | I30: 5.1, 2.4 | J30: 예정 | K30: 0 | L30: 튜토리얼 안에서 사용. 선택 결과는 개인화 메인의 그래프 기준 | M30: =IF(AND($G30<=N$8-1,$H30>=M$8),"X","") | N30: =IF(AND($G30<=O$8-1,$H30>=N$8),"X","") | O30: =IF(AND($G30<=P$8-1,$H30>=O$8),"X","") | P30: =IF(AND($G30<=Q$8-1,$H30>=P$8),"X","") | Q30: =IF(AND($G30<=R$8-1,$H30>=Q$8),"X","") | R30: =IF(AND($G30<=R$8+4,$H30>=R$8),"X","")
A31: 5.4 | B31: 작업 | C31: 프론트엔드 | D31: 가상계좌 화면 구현 | E31: 가상계좌 mock 조회·연결 화면 구현 | F31: B4 | G31: 46318 | H31: 46323 | I31: 5.3, 3.3 | J31: 예정 | K31: 0 | L31: B4가 mock 계좌 화면과 API 연결, F1 스타일·접근성 검토 | M31: =IF(AND($G31<=N$8-1,$H31>=M$8),"X","") | N31: =IF(AND($G31<=O$8-1,$H31>=N$8),"X","") | O31: =IF(AND($G31<=P$8-1,$H31>=O$8),"X","") | P31: =IF(AND($G31<=Q$8-1,$H31>=P$8),"X","") | Q31: =IF(AND($G31<=R$8-1,$H31>=Q$8),"X","") | R31: =IF(AND($G31<=R$8+4,$H31>=R$8),"X","")
A32: 5.5 | B32: 작업 | C32: 프론트엔드 | D32: 최초 1회 튜토리얼 구현 | E32: 관심종목 선택→관련 그래프 표시→노드 클릭→상세 확인→메인 이동 | F32: B3 | G32: 46318 | H32: 46328 | I32: 5.1, 2.4 | J32: 예정 | K32: 0 | L32: B3가 상세 화면, B5가 그래프 상호작용, F1이 공통 UI 검토. AI 질문 예시 답변과 분리 | M32: =IF(AND($G32<=N$8-1,$H32>=M$8),"X","") | N32: =IF(AND($G32<=O$8-1,$H32>=N$8),"X","") | O32: =IF(AND($G32<=P$8-1,$H32>=O$8),"X","") | P32: =IF(AND($G32<=Q$8-1,$H32>=P$8),"X","") | Q32: =IF(AND($G32<=R$8-1,$H32>=Q$8),"X","") | R32: =IF(AND($G32<=R$8+4,$H32>=R$8),"X","")
A33: 5.6 | B33: 작업 | C33: 프론트엔드 | D33: 개인화 메인·관심종목 그래프 | E33: 저장된 관심종목의 연결 그래프·내 종목 관련 노드·뉴스·영향 분석 표시 | F33: B5 | G33: 46315 | H33: 46325 | I33: 5.1, 2.5 | J33: 예정 | K33: 0 | L33: 로그인 후 재방문 시 직행. G5/G6, N9/N11 조회 결과 연결 | M33: =IF(AND($G33<=N$8-1,$H33>=M$8),"X","") | N33: =IF(AND($G33<=O$8-1,$H33>=N$8),"X","") | O33: =IF(AND($G33<=P$8-1,$H33>=O$8),"X","") | P33: =IF(AND($G33<=Q$8-1,$H33>=P$8),"X","") | Q33: =IF(AND($G33<=R$8-1,$H33>=Q$8),"X","") | R33: =IF(AND($G33<=R$8+4,$H33>=R$8),"X","")
A34: 6.1 | B34: 작업 | C34: 통합 | D34: 인증·비회원 통합 | E34: 화면과 인증/권한 API 연결·오류 확인 | F34: B1 | G34: 46317 | H34: 46323 | I34: 4.1, 4.2, 5.2 | J34: 예정 | K34: 0 | L34: B1 인증·비회원 화면 연동, F1 확인 | M34: =IF(AND($G34<=N$8-1,$H34>=M$8),"X","") | N34: =IF(AND($G34<=O$8-1,$H34>=N$8),"X","") | O34: =IF(AND($G34<=P$8-1,$H34>=O$8),"X","") | P34: =IF(AND($G34<=Q$8-1,$H34>=P$8),"X","") | Q34: =IF(AND($G34<=R$8-1,$H34>=Q$8),"X","") | R34: =IF(AND($G34<=R$8+4,$H34>=R$8),"X","")
A35: 6.2 | B35: 작업 | C35: 통합 | D35: 종목·가상계좌 데이터 통합 | E35: mock 계좌·검색·선택 결과 연결 | F35: B4 | G35: 46323 | H35: 46328 | I35: 4.3, 4.4, 5.3, 5.4 | J35: 예정 | K35: 0 | L35: B4 계좌·관심종목 연동, F1 화면 확인 | M35: =IF(AND($G35<=N$8-1,$H35>=M$8),"X","") | N35: =IF(AND($G35<=O$8-1,$H35>=N$8),"X","") | O35: =IF(AND($G35<=P$8-1,$H35>=O$8),"X","") | P35: =IF(AND($G35<=Q$8-1,$H35>=P$8),"X","") | Q35: =IF(AND($G35<=R$8-1,$H35>=Q$8),"X","") | R35: =IF(AND($G35<=R$8+4,$H35>=R$8),"X","")
A36: 6.3 | B36: 작업 | C36: 통합 | D36: 튜토리얼·개인화 메인 통합 | E36: 최초/재방문 분기, 종목 선택·그래프·노드 상세·완료·메인 그래프 연결 확인 | F36: B2 | G36: 46325 | H36: 46329 | I36: 4.5, 5.3, 5.5, 5.6, G6, N9, T8 | J36: 예정 | K36: 0 | L36: T1~T10 사용자 흐름 상세 WBS 기준으로 통합 | M36: =IF(AND($G36<=N$8-1,$H36>=M$8),"X","") | N36: =IF(AND($G36<=O$8-1,$H36>=N$8),"X","") | O36: =IF(AND($G36<=P$8-1,$H36>=O$8),"X","") | P36: =IF(AND($G36<=Q$8-1,$H36>=P$8),"X","") | Q36: =IF(AND($G36<=R$8-1,$H36>=Q$8),"X","") | R36: =IF(AND($G36<=R$8+4,$H36>=R$8),"X","")
A37: M3 | B37: 마일스톤 | C37: 통합 | D37: 기능 통합 완료 | E37: 전체 진입 경로를 스테이징에서 시연 | F37: 전체 | G37: 46329 | H37: 46329 | I37: 6.1, 6.2, 6.3, N9, N11 | J37: 예정 | K37: 0 | M37: =IF(AND($G37<=N$8-1,$H37>=M$8),"X","") | N37: =IF(AND($G37<=O$8-1,$H37>=N$8),"X","") | O37: =IF(AND($G37<=P$8-1,$H37>=O$8),"X","") | P37: =IF(AND($G37<=Q$8-1,$H37>=P$8),"X","") | Q37: =IF(AND($G37<=R$8-1,$H37>=Q$8),"X","") | R37: =IF(AND($G37<=R$8+4,$H37>=R$8),"X","")
A38: 7.1 | B38: 작업 | C38: 검증 | D38: 테스트 시나리오 작성 | E38: 최초 로그인·재방문, 관심종목 0개, 그래프 노드·상세·메인·뉴스 자동 분석 시나리오 | F38: B3 | G38: 46317 | H38: 46323 | I38: M2 | J38: 예정 | K38: 0 | L38: B3 시나리오 작성, B1·B2·B4 API별 검토 | M38: =IF(AND($G38<=N$8-1,$H38>=M$8),"X","") | N38: =IF(AND($G38<=O$8-1,$H38>=N$8),"X","") | O38: =IF(AND($G38<=P$8-1,$H38>=O$8),"X","") | P38: =IF(AND($G38<=Q$8-1,$H38>=P$8),"X","") | Q38: =IF(AND($G38<=R$8-1,$H38>=Q$8),"X","") | R38: =IF(AND($G38<=R$8+4,$H38>=R$8),"X","")
A39: 7.2 | B39: 작업 | C39: 검증 | D39: 기능·mock 데이터 테스트 | E39: 최초 1회 튜토리얼·재방문 우회·메인 개인화 그래프와 뉴스 수집/분석 확인 | F39: B2 | G39: 46324 | H39: 46330 | I39: T9, N8, N9, N11 | J39: 예정 | K39: 0 | L39: N12 종단 간 검증 결과와 함께 확인 | M39: =IF(AND($G39<=N$8-1,$H39>=M$8),"X","") | N39: =IF(AND($G39<=O$8-1,$H39>=N$8),"X","") | O39: =IF(AND($G39<=P$8-1,$H39>=O$8),"X","") | P39: =IF(AND($G39<=Q$8-1,$H39>=P$8),"X","") | Q39: =IF(AND($G39<=R$8-1,$H39>=Q$8),"X","") | R39: =IF(AND($G39<=R$8+4,$H39>=R$8),"X","")
A40: 7.3 | B40: 작업 | C40: 검증 | D40: 반응형·접근성 점검 | E40: 모바일 화면·키보드 이동·알림 가독성 확인 | F40: B5 | G40: 46328 | H40: 46330 | I40: 5.5, 5.6 | J40: 예정 | K40: 0 | L40: B5 접근성·사용성 점검, F1 수정 | M40: =IF(AND($G40<=N$8-1,$H40>=M$8),"X","") | N40: =IF(AND($G40<=O$8-1,$H40>=N$8),"X","") | O40: =IF(AND($G40<=P$8-1,$H40>=O$8),"X","") | P40: =IF(AND($G40<=Q$8-1,$H40>=P$8),"X","") | Q40: =IF(AND($G40<=R$8-1,$H40>=Q$8),"X","") | R40: =IF(AND($G40<=R$8+4,$H40>=R$8),"X","")
A41: 7.4 | B41: 작업 | C41: 검증 | D41: 결함 수정·재검증 | E41: 우선순위 높은 결함 해결·회귀 확인 | F41: B2 | G41: 46329 | H41: 46331 | I41: 7.2, 7.3 | J41: 예정 | K41: 0 | L41: B2가 수정 우선순위 관리, 각 주담당이 소유 기능 수정 | M41: =IF(AND($G41<=N$8-1,$H41>=M$8),"X","") | N41: =IF(AND($G41<=O$8-1,$H41>=N$8),"X","") | O41: =IF(AND($G41<=P$8-1,$H41>=O$8),"X","") | P41: =IF(AND($G41<=Q$8-1,$H41>=P$8),"X","") | Q41: =IF(AND($G41<=R$8-1,$H41>=Q$8),"X","") | R41: =IF(AND($G41<=R$8+4,$H41>=R$8),"X","")
A42: 8.1 | B42: 작업 | C42: 출시 | D42: MVP 시연·수용 확인 | E42: 첫 사용자 튜토리얼→개인화 메인과 자동 수집 뉴스 영향 분석 시연 | F42: A1 | G42: 46331 | H42: 46331 | I42: M3, N12 | J42: 예정 | K42: 0 | L42: 최초 로그인과 재방문 두 경로 모두 시연. AI 질문 예시 답변은 별도 확인 | M42: =IF(AND($G42<=N$8-1,$H42>=M$8),"X","") | N42: =IF(AND($G42<=O$8-1,$H42>=N$8),"X","") | O42: =IF(AND($G42<=P$8-1,$H42>=O$8),"X","") | P42: =IF(AND($G42<=Q$8-1,$H42>=P$8),"X","") | Q42: =IF(AND($G42<=R$8-1,$H42>=Q$8),"X","") | R42: =IF(AND($G42<=R$8+4,$H42>=R$8),"X","")
...

Sheet 튜토리얼·메인 흐름
A2: 첫 로그인 튜토리얼 → 개인화 메인 WBS
A3: 최초 로그인 | B3: 메인→로그인 성공→튜토리얼 미완료 확인→관심종목 선택→그래프→노드 상세→완료→메인
A4: 재방문 로그인 | B4: 로그인 성공→튜토리얼 완료 확인→개인화 메인으로 바로 이동
A5: 메인 화면 | B5: 저장된 관심종목 연결 그래프와 내 종목 관련 노드·뉴스·영향 분석 표시
A6: 예외 조건 | B6: 관심종목 0개면 다음 버튼 차단. 그래프/뉴스가 비면 빈 상태 표시. 완료 전 이탈 시 다시 이어서 진행
A7: 이 탭은 기존 WBS의 인증·종목 선택·GraphDB·화면 작업을 사용자 순서대로 풀어 쓴 상세 일정입니다. 중복 작업으로 인원을 추가 집계하지 않습니다.
A8: WBS | B8: 사용자 순서·작업 | C8: 완료 기준 | D8: 주담당 | E8: 시작 | F8: 완료 | G8: 의존 | H8: 상태 | I8: 진행률 | J8: 기존 WBS·비고
A9: T1 | B9: 메인에서 로그인 진입 | C9: 로그인 전 메인에서 로그인 버튼·로그인 화면 진입 | D9: F1 | E9: 46309 | F9: 46317 | G9: 5.1, 5.2 | H9: 예정 | I9: 0 | J9: 메인→로그인 시작점
A10: T2 | B10: 최초 사용자 분기 | C10: 로그인 성공 후 완료 상태가 없으면 튜토리얼, 있으면 메인 | D10: B1 | E10: 46316 | F10: 46322 | G10: 4.1, 4.5 | H10: 예정 | I10: 0 | J10: 완료 상태는 회원 계정에 저장
A11: T3 | B11: 관심종목 선정 | C11: 관심종목 검색·1개 이상 저장, 0개면 다음 단계 차단 | D11: F1 | E11: 46315 | F11: 46322 | G11: 4.4, 5.3 | H11: 예정 | I11: 0 | J11: 가상계좌 연결 없이도 튜토리얼 진행 가능
A12: T4 | B12: 선택 종목 그래프 조회 | C12: 선택한 종목과 연결된 기업·이슈·뉴스 노드 응답 | D12: B2 | E12: 46311 | F12: 46318 | G12: G5, 4.4 초안 | H12: 예정 | I12: 0 | J12: 종목 선택 결과로 그래프 필터
A13: T5 | B13: 관련 그래프 표시·노드 클릭 | C13: 그래프 표시, 노드 선택 상태와 상세 이동 동작 | D13: B5 | E13: 46315 | F13: 46323 | G13: G6, T4 | H13: 예정 | I13: 0 | J13: 선택된 노드가 무엇인지 화면에 표시
A14: T6 | B14: 클릭 노드 상세 API | C14: 선택 노드의 기사·영향 이유·근거·관련 종목 반환 | D14: B4 | E14: 46318 | F14: 46325 | G14: G5, N9 초안 | H14: 예정 | I14: 0 | J14: 노드 종류별 빈 값·오류 처리
A15: T7 | B15: 노드 상세 화면 | C15: 클릭한 노드의 상세 내용·연결 뉴스 확인 | D15: B3 | E15: 46321 | F15: 46328 | G15: T5, T6 초안 | H15: 예정 | I15: 0 | J15: 원문 링크·영향 분석 근거 표시
A16: T8 | B16: 튜토리얼 완료·메인 이동 | C16: 노드 상세 확인 뒤 완료 저장, 개인화 메인으로 이동 | D16: B1 | E16: 46324 | F16: 46328 | G16: T2, T7 초안 | H16: 예정 | I16: 0 | J16: 중간 이탈은 미완료로 유지
A17: T9 | B17: 메인 관심종목 그래프·뉴스 | C17: 저장 종목 그래프와 관련 노드·뉴스·영향 결과 표시 | D17: B5 | E17: 46324 | F17: 46329 | G17: T4, N9, N11 | H17: 예정 | I17: 0 | J17: 재방문 시 바로 이 화면
A18: T10 | B18: 전체 경로 통합 검증 | C18: 최초 로그인 1회·재방문 우회·0개 차단·노드 상세·메인 확인 | D18: B2 | E18: 46329 | F18: 46331 | G18: T1~T9 | H18: 예정 | I18: 0 | J18: F1 사용성 확인, B3/B4 데이터·API 결함 수정

Sheet 그래프DB 일정
A2: 그래프 DB 구축 WBS
A3: 기준 범위 | B3: 기초 그래프: 종목 20~30개·검증용 뉴스 샘플. 자동 수집 뉴스는 N8에서 지속 적재
A4: 그래프 핵심 3명 | B4: 10월 6일~19일 · 9작업일
A5: 그래프 핵심 2명 | B5: 10월 6일~22일 · 12작업일
A6: 역할 | B6: B2: 그래프 DB·통합 B3: 뉴스 데이터·튜토리얼 B4: 조회 API·mock 계좌 B5: 그래프·메인 화면
A7: G8은 그래프 기반 인계입니다. 뉴스 자동 수집·분석 결과의 지속 적재와 전체 완성은 뉴스 자동화 일정의 N8~N12를 참조합니다.
A8: WBS | B8: 작업 | C8: 완료 기준 | D8: 담당 역할 | E8: 3명 시작 | F8: 3명 완료 | G8: 2명 시작 | H8: 2명 완료 | I8: 참조·의존 | J8: 상태 | K8: 진행률 | L8: 비고
A9: G1 | B9: 관계 모델 설계 | C9: 기업·기사·사건 노드, 언급·영향 관계와 ID 규칙 | D9: B2 | E9: 46301 | F9: 46302 | G9: 46301 | H9: 46302 | I9: M1 | J9: 예정 | K9: 0 | L9: B2 주도, B3 종목·기사 식별자 검토
A10: G2 | B10: 기업·기사 샘플 정리 | C10: 종목 코드·별칭, 크롤러/분석 검증용 뉴스 샘플과 출처 정리 | D10: B3 | E10: 46301 | F10: 46308 | G10: 46301 | H10: 46308 | I10: G1 초안 | J10: 예정 | K10: 0 | L10: 자동 수집 파이프라인의 테스트 데이터로 사용
A11: G3 | B11: 그래프 DB 설정·적재 | C11: 제약조건·인덱스·중복 방지·초기 데이터 적재 | D11: B2 | E11: 46303 | F11: 46308 | G11: 46303 | H11: 46308 | I11: G1, G2 일부 | J11: 예정 | K11: 0 | L11: Neo4j 등 제품 선택 후 설치
A12: G4 | B12: 뉴스·사건·기업 관계 검수 | C12: 사건별 영향 관계·이유·근거 링크 검수 | D12: B3 | E12: 46308 | F12: 46311 | G12: 46308 | H12: 46311 | I12: G2, G3 | J12: 예정 | K12: 0 | L12: 오연결·중복 확인
A13: G5 | B13: 그래프 조회 API | C13: 관심종목 관련 뉴스·이슈·영향 경로와 클릭한 노드의 상세 응답 | D13: B4 | E13: 46308 | F13: 46311 | G13: 46308 | H13: 46311 | I13: G3 | J13: 예정 | K13: 0 | L13: 튜토리얼/메인 공통 API. 노드 ID로 상세 기사·이유·근거 조회
A14: G6 | B14: 클릭형 그래프·노드 상세 연결 | C14: 관심종목 그래프 표시, 노드 클릭→상세 화면 이동 | D14: B5 | E14: 46310 | F14: 46314 | G14: 46314 | H14: 46316 | I14: G4·G5 초안 | J14: 예정 | K14: 0 | L14: B5 그래프 상호작용, B3 상세 화면, F1 UI 검토
A15: G7 | B15: 통합 테스트·수정 | C15: 대표 종목 경로·노드 클릭·상세·빈 결과 확인 | D15: B2 | E15: 46311 | F15: 46314 | G15: 46316 | H15: 46317 | I15: G4, G5, G6 | J15: 예정 | K15: 0 | L15: B2 통합 테스트 주도, B3 데이터·B4 API·B5 화면 확인
A16: G8 | B16: 기초 그래프 인계 | C16: 관심종목→관련 그래프→노드 상세 시연, 자동 적재는 N8에서 연계 | D16: 전체 | E16: 46314 | F16: 46314 | G16: 46317 | H16: 46317 | I16: G7 | J16: 예정 | K16: 0 | L16: GraphDB 최종 완료가 아닌 기반 인계. 뉴스 자동화는 N8~N12

Sheet 뉴스 자동수집·분석
A2: 뉴스 자동 수집 · 종목별 영향 분석 WBS
A3: MVP 범위 | B3: 확정한 뉴스 출처 1~2곳에서 정기 수집 → 정제/중복 제거 → 종목 연결 → 이슈·영향 분석 → GraphDB/화면 반영
A4: 분석 결과 | B4: 종목·기사·핵심 이슈·영향 방향(긍정/부정/중립)·이유·근거 링크·분석 시각
A5: 운영 기준 | B5: 새 기사 자동 반영, 실패 재시도·중복 방지·작업 상태 확인. 대표 기사 수동 검수
A6: 선행 조건 | B6: 9/30~10/2 뉴스 출처·접근 방법·분석 기준 확정. 출처 미확정 시 이후 일정 재산정
A7: 10/19 G8은 GraphDB 기반 인계, 11/3 N9~N11은 자동 수집·분석 통합 목표입니다. 11/4~5 검증 후 11/6 MVP를 시연합니다.
A8: WBS | B8: 작업 | C8: 완료 기준 | D8: 주담당 | E8: 시작 | F8: 완료 | G8: 의존 | H8: 상태 | I8: 진행률 | J8: 비고
A9: N1 | B9: 뉴스 출처·분석 기준 확정 | C9: 출처 1~2곳, 수집 범위·주기, 종목별 영향 분류 기준 확정 | D9: B3 | E9: 46295 | F9: 46297 | G9: M1 초안 | H9: 예정 | I9: 0 | J9: A1 분석 기준, B2 ID 규칙 검토
A10: N2 | B10: 뉴스 크롤러 구현 | C10: 선정 출처에서 제목·본문·일시·원문 링크 자동 수집 | D10: B3 | E10: 46301 | F10: 46308 | G10: N1 | H10: 예정 | I10: 0 | J10: 출처별 수집 오류·형식 변경 확인
A11: N3 | B11: 정기 실행·재시도 | C11: 수집 작업을 자동 실행하고 실패 시 재시도·상태 기록 | D11: B4 | E11: 46307 | F11: 46314 | G11: N2 초안 | H11: 예정 | I11: 0 | J11: A1 스테이징 환경 지원
A12: N4 | B12: 정제·중복 제거 | C12: 기사 형식 통일, 중복·빈 본문·잘못된 날짜 제거 | D12: B3 | E12: 46308 | F12: 46315 | G12: N2 | H12: 예정 | I12: 0 | J12: 원문 링크와 수집 시각 유지
A13: N5 | B13: 기사·종목 연결 | C13: 기업명·별칭·종목 코드 매칭, 다중 종목 기사 처리 | D13: B2 | E13: 46311 | F13: 46318 | G13: N4, G1 | H13: 예정 | I13: 0 | J13: 매칭 실패는 검수 대상으로 분리
A14: N6 | B14: 이슈·영향 자동 분석 | C14: 종목별 핵심 이슈·영향 방향·이유·근거 문장 생성 | D14: A1 | E14: 46311 | F14: 46322 | G14: N1, N4 초안 | H14: 예정 | I14: 0 | J14: AI 질문 예시 답변과 별도 기능
A15: N7 | B15: 분석 결과 품질 검수 | C15: 대표 기사에서 종목 연결·영향 방향·이유·근거 확인 | D15: A1 | E15: 46317 | F15: 46324 | G15: N5, N6 | H15: 예정 | I15: 0 | J15: 오분류·근거 없음·중립 사례 보완
A16: N8 | B16: GraphDB 자동 적재 | C16: 새 기사·이슈·영향 관계를 중복 없이 갱신 | D16: B2 | E16: 46318 | F16: 46324 | G16: G8, N5, N6 | H16: 예정 | I16: 0 | J16: 기사 원문 링크와 분석 시각 저장
A17: N9 | B17: 분석 결과 조회 API | C17: 종목별 최신 기사·영향 방향·이유·근거 응답 | D17: B4 | E17: 46321 | F17: 46328 | G17: N7, N8 | H17: 예정 | I17: 0 | J17: 빈 결과·수집 지연 상태도 반환
A18: N10 | B18: 수집 상태·오류 확인 | C18: 최종 성공 시각·실패 건·재처리 방법 확인 | D18: B1 | E18: 46324 | F18: 46328 | G18: N3, N8 | H18: 예정 | I18: 0 | J18: 운영 인계 자료에 복구 절차 포함
A19: N11 | B19: 영향 분석 화면 표시 | C19: 종목별 영향 카드·기사 링크·분석 시각 표시 | D19: B5 | E19: 46324 | F19: 46328 | G19: N9 초안 | H19: 예정 | I19: 0 | J19: F1 UI 규칙·접근성 검토
A20: N12 | B20: 자동 수집→시연 검증 | C20: 새 기사 수집부터 분석·GraphDB·화면 반영까지 검증 | D20: F1 | E20: 46329 | F20: 46331 | G20: N9, N10, N11 | H20: 예정 | I20: 0 | J20: B2~B4 결함 수정, A1 분석 결과 검수

Sheet 팀 배치
A2: 7명 배분 · 첫 로그인 튜토리얼 반영
A3: 배분 기준 | B3: 주담당 1명 기준. 뉴스 자동화 추가로 담당 건수가 달라졌으며, 작업일·난이도를 함께 확인해 조정.
A4: MVP 범위 | B4: 가상계좌 mock, 뉴스 자동 수집·종목별 영향 분석, 첫 로그인 1회 튜토리얼, AI 질문 예시 답변.
A5: 프론트 지원 | B5: F1은 공통 UI·로그인·관심종목 선택. B3 노드 상세, B4 상세 API, B5 그래프·개인화 메인 담당.
A7: ID | B7: 주 담당 | C7: 주담당 작업 | D7: 협업·인계 | E7: 집중 기간 | F7: 완료 기준 | G7: 주담당 건수
A8: F1 | B8: 프론트 | C8: 공통 UI·로그인·관심종목 선택·최초 사용자 흐름 사용성 확인 | D8: B3·B4·B5 화면 UI 검토 | E8: 10/6~11/4 | F8: 공통 UI·핵심 화면·자동 뉴스 흐름 검증 | G8: =COUNTIF(WBS!$F$9:$F$44,A8)+COUNTIF('그래프DB 일정'!$D$9:$D$15,A8)+COUNTIF('뉴스 자동수집·분석'!$D$9:$D$20,A8)
A9: A1 | B9: AI·클라우드 | C9: 개발 환경·AI 질문 예시 답변·뉴스 영향 분석·배포 | D9: B3 수집 데이터, B2 그래프 적재 연계 | E9: 10/1~11/6 | F9: 종목별 영향 방향·이유·근거 분석 검수 | G9: =COUNTIF(WBS!$F$9:$F$44,A9)+COUNTIF('그래프DB 일정'!$D$9:$D$15,A9)+COUNTIF('뉴스 자동수집·분석'!$D$9:$D$20,A9)
A10: B1 | B10: 백엔드 1 | C10: 인증·최초/재방문 분기·튜토리얼 완료 상태 API | D10: B4 정기 실행 결과 인계 | E10: 10/1~11/3 | F10: 인증 API와 수집 상태·복구 절차 완료 | G10: =COUNTIF(WBS!$F$9:$F$44,A10)+COUNTIF('그래프DB 일정'!$D$9:$D$15,A10)+COUNTIF('뉴스 자동수집·분석'!$D$9:$D$20,A10)
A11: B2 | B11: 백엔드 2 | C11: 그래프 모델·종목별 관계 조회·개인화 메인 통합 | D11: B3 정제 기사, A1 분석 결과 연계 | E11: 10/6~11/5 | F11: 자동 수집 분석 결과가 그래프에 갱신 | G11: =COUNTIF(WBS!$F$9:$F$44,A11)+COUNTIF('그래프DB 일정'!$D$9:$D$15,A11)+COUNTIF('뉴스 자동수집·분석'!$D$9:$D$20,A11)
A12: B3 | B12: 백엔드 3 | C12: 뉴스 수집·정제, 튜토리얼 노드 상세 화면 | D12: A1 영향 기준, F1 화면 UI 검토 | E12: 10/6~11/4 | F12: 출처 뉴스 자동 수집·정제 및 화면 완료 | G12: =COUNTIF(WBS!$F$9:$F$44,A12)+COUNTIF('그래프DB 일정'!$D$9:$D$15,A12)+COUNTIF('뉴스 자동수집·분석'!$D$9:$D$20,A12)
A13: B4 | B13: 백엔드 4 | C13: 그래프 조회·클릭 노드 상세 API, mock 계좌 | D13: B2 그래프 적재, F1 UI 검토 | E13: 9/30~11/2 | F13: 수집·분석 조회 API와 계좌 연동 완료 | G13: =COUNTIF(WBS!$F$9:$F$44,A13)+COUNTIF('그래프DB 일정'!$D$9:$D$15,A13)+COUNTIF('뉴스 자동수집·분석'!$D$9:$D$20,A13)
A14: B5 | B14: 백엔드 5·지원 | C14: 그래프 노드 클릭·개인화 메인·뉴스 영향 화면 | D14: B4 분석 API, F1 공통 UI 활용 | E14: 9/29~11/4 | F14: 뉴스 영향 카드·메인 표시·접근성 확인 | G14: =COUNTIF(WBS!$F$9:$F$44,A14)+COUNTIF('그래프DB 일정'!$D$9:$D$15,A14)+COUNTIF('뉴스 자동수집·분석'!$D$9:$D$20,A14)
A16: 주담당 건수는 기본 WBS·GraphDB·뉴스 자동화 기준입니다. 튜토리얼 탭은 같은 작업을 사용자 순서로 푼 상세 일정이므로 중복 집계하지 않습니다.
